DEBUG 2017-02-16 12:00:49,012: 	 Executing command: 'status'
DEBUG 2017-02-16 12:00:49,013: 	 Found CRAB cache file /home/fengyb/.crab3
DEBUG 2017-02-16 12:00:49,020: 	 Checking credentials
DEBUG 2017-02-16 12:00:49,020: 	 Found proxy file /tmp/x509up_u1701
DEBUG 2017-02-16 12:00:49,020: 	 Getting proxy life time left
DEBUG 2017-02-16 12:00:49,123: 	 Executing : 
 command : voms-proxy-info -file /tmp/x509up_u1701 -timeleft
 output : 85647

 error: 
 retcode : 0
DEBUG 2017-02-16 12:00:49,227: 	 Executing : 
 command : voms-proxy-info -file /tmp/x509up_u1701 -actimeleft
 output : 85647

 error: 
 retcode : 0
DEBUG 2017-02-16 12:00:49,227: 	 Proxy valid for 23:47:27 hours
ERROR 2017-02-16 12:00:49,228: 	 Cannot find .requestcache file in CRAB project directory /data/users/fengyb/CMSSW_7_6_3/src/EmergingJetAnalysis/crabTasks/crab_Analysis-20170215-2017-0215-v0/crab_Analysis-20170215-GJetDataRun2015D-v4-2017-0215-184624
ERROR 2017-02-16 12:00:49,228: 	 Caught exception
Traceback (most recent call last):
  File "/cvmfs/cms.cern.ch/crab3/slc6_amd64_gcc493/cms/crabclient/3.3.1702/bin/crab", line 160, in <module>
    client()
  File "/cvmfs/cms.cern.ch/crab3/slc6_amd64_gcc493/cms/crabclient/3.3.1702/bin/crab", line 146, in __call__
    self.cmd = sub_cmd(self.logger, args[1:])
  File "/cvmfs/cms.cern.ch/crab3/slc6_amd64_gcc493/cms/crabclient/3.3.1702/lib/python2.7/site-packages/CRABClient/Commands/SubCommand.py", line 321, in __init__
    self.loadLocalCache(proxyOptsSetPlace)
  File "/cvmfs/cms.cern.ch/crab3/slc6_amd64_gcc493/cms/crabclient/3.3.1702/lib/python2.7/site-packages/CRABClient/Commands/SubCommand.py", line 450, in loadLocalCache
    raise ex
CachefileNotFoundException: Cannot find .requestcache file in CRAB project directory /data/users/fengyb/CMSSW_7_6_3/src/EmergingJetAnalysis/crabTasks/crab_Analysis-20170215-2017-0215-v0/crab_Analysis-20170215-GJetDataRun2015D-v4-2017-0215-184624
DEBUG 2017-02-17 11:30:51,756: 	 Executing command: 'status'
DEBUG 2017-02-17 11:30:51,757: 	 Found CRAB cache file /home/fengyb/.crab3
ERROR 2017-02-17 11:30:51,761: 	 Error: crab_Analysis-20170215-GJetDataRun2015D-v3 is not a valid CRAB project directory.
ERROR 2017-02-17 11:30:51,761: 	 Caught exception
Traceback (most recent call last):
  File "/cvmfs/cms.cern.ch/crab3/slc6_amd64_gcc493/cms/crabclient/3.3.1702/bin/crab", line 160, in <module>
    client()
  File "/cvmfs/cms.cern.ch/crab3/slc6_amd64_gcc493/cms/crabclient/3.3.1702/bin/crab", line 146, in __call__
    self.cmd = sub_cmd(self.logger, args[1:])
  File "/cvmfs/cms.cern.ch/crab3/slc6_amd64_gcc493/cms/crabclient/3.3.1702/lib/python2.7/site-packages/CRABClient/Commands/SubCommand.py", line 257, in __init__
    self.validateOptions()
  File "/cvmfs/cms.cern.ch/crab3/slc6_amd64_gcc493/cms/crabclient/3.3.1702/lib/python2.7/site-packages/CRABClient/Commands/status.py", line 762, in validateOptions
    SubCommand.validateOptions(self)
  File "/cvmfs/cms.cern.ch/crab3/slc6_amd64_gcc493/cms/crabclient/3.3.1702/lib/python2.7/site-packages/CRABClient/Commands/SubCommand.py", line 566, in validateOptions
    raise ConfigurationException(msg)
ConfigurationException: [91mError[0m: crab_Analysis-20170215-GJetDataRun2015D-v3 is not a valid CRAB project directory.
